<?xml version="1.0" ?>
<!-- =================================================================================== -->
<!-- |    This document was autogenerated by xacro from urdf/jaco_robot.urdf.xacro     | -->
<!-- |    EDITING THIS FILE BY HAND IS NOT RECOMMENDED                                 | -->
<!-- =================================================================================== -->
<robot name="jaco" xmlns:controller="http://playerstage.sourceforge.net/gazebo/xmlschema/#controller" xmlns:interface="http://playerstage.sourceforge.net/gazebo/xmlschema/#interface" xmlns:sensor="http://playerstage.sourceforge.net/gazebo/xmlschema/#sensor">
  <link name="base_link">
  </link>
  <!-- fake cylinder which is actually a box -->
  <!--xacro:macro name="cyl_inertia" params="mass r h ">
      <mass value="${mass}"/>
      <inertia
      ixx="${mass / 12.0 * (r*r + h*h)}" ixy="0.0" ixz="0.0"
      iyy="${mass / 12.0 * (h*h + r*r)}" iyz="0.0"
      izz="${mass / 12.0 * (r*r + r*r)}"/>
  </xacro:macro-->
  <!-- ***************** MODEL CORRECTIONS ************************* -->
  <!-- *************************************************************** -->
  <!-- from measurements, pitch is -0.2293 -->
  <!-- MODEL_FIX transforms from wrist to finger mounts -->
  <!--<xacro:property name="f_thb_m_xyz" value=" 0.037  0.001  0.106" />
  <xacro:property name="f_idx_m_xyz" value="-0.034  0.022 0.106" />
  <xacro:property name="f_pnk_m_xyz" value="-0.034 -0.022 0.106" />
  <xacro:property name="f_thb_m_rpy" value="0 -0.2658 ${M_PI-0.226892}" /> 
  <xacro:property name="f_idx_m_rpy" value="0 -0.2293 -0.191986" />
  <xacro:property name="f_pnk_m_rpy" value="0 -0.2293 0.191986" />-->
  <joint name="jaco_arm_joint" type="fixed">
    <origin rpy="0 0 0" xyz="0 0 0"/>
    <parent link="base_link"/>
    <child link="jaco_0_baseA"/>
  </joint>
  <!-- for some reason, material only applies if full name specified...
       these only seem to work in older gazebo versions -->
  <gazebo reference="jaco_ring_">
    <material>Gazebo/Grey</material>
    <implicitSpringDamper>1</implicitSpringDamper>
    <mu1>100000</mu1>
    <mu2>100000</mu2>
    <kp>100000000.0</kp>
    <kd>1.0</kd>
  </gazebo>
  <gazebo reference="_limb">
    <material>Gazebo/FlatBlack</material>
    <implicitSpringDamper>1</implicitSpringDamper>
    <mu1>100000</mu1>
    <mu2>100000</mu2>
    <kp>100000000.0</kp>
    <kd>1.0</kd>
  </gazebo>
  <gazebo reference="_finger">
    <material>Gazebo/Grey</material>
    <implicitSpringDamper>1</implicitSpringDamper>
    <mu1>100000</mu1>
    <mu2>100000</mu2>
    <kp>100000000.0</kp>
    <kd>1.0</kd>
  </gazebo>
  <!-- for some reason, material only applies if full name specified -->
  <gazebo reference="jaco_0_baseA">
    <material>Gazebo/White</material>
    <mu1>100000</mu1>
    <mu2>100000</mu2>
    <kp>100000000.0</kp>
    <kd>1.0</kd>
  </gazebo>
  <gazebo reference="jaco_0_baseB_limb">
    <material>Gazebo/FlatBlack</material>
    <mu1>100000</mu1>
    <mu2>100000</mu2>
    <kp>100000000.0</kp>
    <kd>1.0</kd>
  </gazebo>
  <gazebo reference="jaco_ring_1">
    <material>Gazebo/Grey</material>
    <mu1>100000</mu1>
    <mu2>100000</mu2>
    <kp>100000000.0</kp>
    <kd>1.0</kd>
  </gazebo>
  <gazebo reference="jaco_ring_2">
    <material>Gazebo/Grey</material>
    <mu1>100000</mu1>
    <mu2>100000</mu2>
    <kp>100000000.0</kp>
    <kd>1.0</kd>
  </gazebo>
  <gazebo reference="jaco_ring_3">
    <material>Gazebo/Grey</material>
    <mu1>100000</mu1>
    <mu2>100000</mu2>
    <kp>100000000.0</kp>
    <kd>1.0</kd>
  </gazebo>
  <gazebo reference="jaco_ring_4">
    <material>Gazebo/Grey</material>
    <mu1>100000</mu1>
    <mu2>100000</mu2>
    <kp>100000000.0</kp>
    <kd>1.0</kd>
  </gazebo>
  <gazebo reference="jaco_ring_5">
    <material>Gazebo/Grey</material>
    <mu1>100000</mu1>
    <mu2>100000</mu2>
    <kp>100000000.0</kp>
    <kd>1.0</kd>
  </gazebo>
  <gazebo reference="jaco_ring_6">
    <material>Gazebo/Grey</material>
    <mu1>100000</mu1>
    <mu2>100000</mu2>
    <kp>100000000.0</kp>
    <kd>1.0</kd>
  </gazebo>
  <gazebo reference="jaco_1_shoulder_limb">
    <material>Gazebo/FlatBlack</material>
    <mu1>100000</mu1>
    <mu2>100000</mu2>
    <kp>100000000.0</kp>
    <kd>1.0</kd>
  </gazebo>
  <gazebo reference="jaco_2_upperarm_limb">
    <material>Gazebo/FlatBlack</material>
    <mu1>100000</mu1>
    <mu2>100000</mu2>
    <kp>100000000.0</kp>
    <kd>1.0</kd>
  </gazebo>
  <gazebo reference="jaco_3_forearm_limb">
    <material>Gazebo/FlatBlack</material>
    <mu1>100000</mu1>
    <mu2>100000</mu2>
    <kp>100000000.0</kp>
    <kd>1.0</kd>
  </gazebo>
  <gazebo reference="jaco_4_upperwrist_limb">
    <material>Gazebo/FlatBlack</material>
    <mu1>100000</mu1>
    <mu2>100000</mu2>
    <kp>100000000.0</kp>
    <kd>1.0</kd>
  </gazebo>
  <gazebo reference="jaco_5_lowerwrist_limb">
    <material>Gazebo/FlatBlack</material>
    <mu1>100000</mu1>
    <mu2>100000</mu2>
    <kp>100000000.0</kp>
    <kd>1.0</kd>
  </gazebo>
  <gazebo reference="jaco_6_hand_limb">
    <material>Gazebo/FlatBlack</material>
    <mu1>100000</mu1>
    <mu2>100000</mu2>
    <kp>100000000.0</kp>
    <kd>1.0</kd>
  </gazebo>
  <gazebo reference="jaco_fingers_base_link">
    <material>Gazebo/FlatBlack</material>
    <mu1>100000</mu1>
    <mu2>100000</mu2>
    <kp>100000000.0</kp>
    <kd>1.0</kd>
  </gazebo>
  <gazebo reference="jaco_7_finger_mount_index">
    <material>Gazebo/FlatBlack</material>
    <mu1>100000</mu1>
    <mu2>100000</mu2>
    <kp>100000000.0</kp>
    <kd>1.0</kd>
  </gazebo>
  <gazebo reference="jaco_7_finger_mount_thumb">
    <material>Gazebo/FlatBlack</material>
    <mu1>100000</mu1>
    <mu2>100000</mu2>
    <kp>100000000.0</kp>
    <kd>1.0</kd>
  </gazebo>
  <gazebo reference="jaco_7_finger_mount_pinkie">
    <material>Gazebo/FlatBlack</material>
    <mu1>100000</mu1>
    <mu2>100000</mu2>
    <kp>100000000.0</kp>
    <kd>1.0</kd>
  </gazebo>
  <gazebo reference="jaco_8_finger_thumb">
    <material>Gazebo/Grey</material>
    <mu1>100000</mu1>
    <mu2>100000</mu2>
    <kp>100000000.0</kp>
    <kd>1.0</kd>
  </gazebo>
  <gazebo reference="jaco_8_finger_index">
    <material>Gazebo/Grey</material>
    <mu1>100000</mu1>
    <mu2>100000</mu2>
    <kp>100000000.0</kp>
    <kd>1.0</kd>
  </gazebo>
  <gazebo reference="jaco_8_finger_pinkie">
    <material>Gazebo/Grey</material>
    <mu1>100000</mu1>
    <mu2>100000</mu2>
    <kp>100000000.0</kp>
    <kd>1.0</kd>
  </gazebo>
  <gazebo reference="jaco_9_finger_thumb_tip">
    <material>Gazebo/Grey</material>
    <mu1>100000</mu1>
    <mu2>100000</mu2>
    <kp>100000000.0</kp>
    <kd>1.0</kd>
  </gazebo>
  <gazebo reference="jaco_9_finger_index_tip">
    <material>Gazebo/Grey</material>
    <mu1>100000</mu1>
    <mu2>100000</mu2>
    <kp>100000000.0</kp>
    <kd>1.0</kd>
  </gazebo>
  <gazebo reference="jaco_9_finger_pinkie_tip">
    <material>Gazebo/Grey</material>
    <mu1>100000</mu1>
    <mu2>100000</mu2>
    <kp>100000000.0</kp>
    <kd>1.0</kd>
  </gazebo>
  <gazebo reference="jaco_finger_joint_0">
    <provideFeedback value="true"/>
  </gazebo>
  <gazebo reference="jaco_finger_joint_2">
    <provideFeedback value="true"/>
  </gazebo>
  <gazebo reference="jaco_finger_joint_4">
    <provideFeedback value="true"/>
  </gazebo>
  <link name="jaco_0_baseA">
    <inertial>
      <origin rpy="0 0 0" xyz="0 0 0.03"/>
      <mass value="0.5688"/>
      <inertia ixx="0.00034928920283759993" ixy="0" ixz="0" iyy="0.00034928920283759993" iyz="0" izz="0.0003685823999999999"/>
    </inertial>
    <visual>
      <origin rpy="0 0 0" xyz="0 0 0"/>
      <geometry>
        <mesh filename="/home/colan/simulations/URDFs/robots/kinova/jaco/meshes/0_baseA.STL" scale="0.98 0.98 0.98"/>
      </geometry>
      <material name="">
        <color rgba="0.65 0.65 0.66 1"/>
      </material>
    </visual>
    <collision>
      <origin rpy="0 0 0" xyz="0 0 0"/>
      <geometry>
        <mesh filename="/home/colan/simulations/URDFs/robots/kinova/jaco/meshes/0_baseA.STL"/>
      </geometry>
    </collision>
  </link>
  <!-- ...........................        -->
  <link name="jaco_0_baseB_limb">
    <inertial>
      <origin rpy="0 0 0" xyz="0 0.04725 0"/>
      <mass value="0.5152"/>
      <inertia ixx="0.0005894830420584" ixy="0" ixz="0" iyy="0.0005894830420584" iyz="0" izz="0.00041216"/>
    </inertial>
    <visual>
      <origin rpy="0 0 0" xyz="0 0 0"/>
      <geometry>
        <mesh filename="/home/colan/simulations/URDFs/robots/kinova/jaco/meshes/0_baseB_limb.STL"/>
      </geometry>
      <material name="">
        <color rgba="0.10 0.10 0.10 1"/>
      </material>
    </visual>
    <collision>
      <origin rpy="0 0 0" xyz="0 0 0"/>
      <geometry>
        <mesh filename="/home/colan/simulations/URDFs/robots/kinova/jaco/meshes/0_baseB_limb.STL"/>
      </geometry>
    </collision>
  </link>
  <joint name="jaco_base_internal" type="fixed">
    <origin rpy="1.5707963267949 0 0" xyz="0 0 0.049"/>
    <parent link="jaco_0_baseA"/>
    <child link="jaco_0_baseB_limb"/>
    <axis xyz="0 0 0"/>
  </joint>
  <link name="jaco_ring_1">
    <inertial>
      <origin rpy="0 0 0" xyz="-3.57503886452221E-16 -1.58125151997128E-15 -5.55111512312578E-17"/>
      <mass value="0.00872"/>
      <inertia ixx="3.7786515520000004e-06" ixy="0" ixz="0" iyy="3.7786515520000004e-06" iyz="0" izz="6.976000000000001e-06"/>
    </inertial>
    <visual>
      <origin rpy="0 0 0" xyz="0 0 0"/>
      <geometry>
        <mesh filename="/home/colan/simulations/URDFs/robots/kinova/jaco/meshes/ring_1.STL"/>
      </geometry>
      <material name="">
        <color rgba="0.50 0.50 0.50 1"/>
      </material>
    </visual>
    <collision>
      <origin rpy="0 0 0" xyz="0 0 0"/>
      <geometry>
        <mesh filename="/home/colan/simulations/URDFs/robots/kinova/jaco/meshes/ring_1.STL"/>
      </geometry>
    </collision>
  </link>
  <joint name="jaco_ring_1_joint" type="fixed">
    <origin rpy="-1.5707963267949 0.211499083190217 -3.14159265358979" xyz="0 0.104 0"/>
    <parent link="jaco_0_baseB_limb"/>
    <child link="jaco_ring_1"/>
    <axis xyz="0 0 0"/>
  </joint>
  <!-- ...........................        -->
  <link name="jaco_1_shoulder_limb">
    <inertial>
      <origin rpy="0 0 0" xyz="0.0120470281905243 0.0657132437750733 0"/>
      <mass value="0.4782"/>
      <inertia ixx="0.0011987230550886002" ixy="0" ixz="0" iyy="0.0011987230550886002" iyz="0" izz="0.00038256000000000005"/>
    </inertial>
    <visual>
      <origin rpy="0 0 0" xyz="0 0 0"/>
      <geometry>
        <mesh filename="/home/colan/simulations/URDFs/robots/kinova/jaco/meshes/1_shoulder_limb.STL"/>
      </geometry>
      <material name="">
        <color rgba="0.10 0.10 0.10 1"/>
      </material>
    </visual>
    <!--     <visual>
      <origin xyz="0 0 0" rpy="0 0 0" />
      <geometry>
        <sphere radius="0.005"/>
      </geometry>
      <material name="">
        <color rgba="0.10 0.10 0.10 1" />
      </material>
    </visual>
-->
    <collision>
      <origin rpy="0 0 0" xyz="0 0 0"/>
      <geometry>
        <mesh filename="/home/colan/simulations/URDFs/robots/kinova/jaco/meshes/1_shoulder_limb.STL"/>
      </geometry>
    </collision>
  </link>
  <joint name="jaco_arm_0_joint" type="revolute">
    <dynamics damping="0.5" friction="0.5"/>
    <origin rpy="0 1.5707963267949 0" xyz="0 0.104 0"/>
    <limit effort="8" lower="-6.283185307" upper="6.283185307" velocity="1.0"/>
    <parent link="jaco_0_baseB_limb"/>
    <child link="jaco_1_shoulder_limb"/>
    <axis xyz="0 1 0"/>
  </joint>
  <!-- ...........................        -->
  <link name="jaco_ring_2">
    <inertial>
      <origin rpy="0 0 0" xyz="0 0 0"/>
      <mass value="0.00872"/>
      <inertia ixx="3.7786515520000004e-06" ixy="0" ixz="0" iyy="3.7786515520000004e-06" iyz="0" izz="6.976000000000001e-06"/>
    </inertial>
    <visual>
      <origin rpy="0 0 0" xyz="-0.0005 -0.003 -0.001"/>
      <geometry>
        <mesh filename="/home/colan/simulations/URDFs/robots/kinova/jaco/meshes/ring_2.STL"/>
      </geometry>
      <material name="">
        <color rgba="0.50 0.50 0.50 1"/>
      </material>
    </visual>
    <collision>
      <origin rpy="0 0 0" xyz="-0.0005 -0.003 -0.001"/>
      <geometry>
        <mesh filename="/home/colan/simulations/URDFs/robots/kinova/jaco/meshes/ring_2.STL"/>
      </geometry>
    </collision>
  </link>
  <joint name="jaco_ring_2_joint" type="fixed">
    <origin rpy="-1.57079632679488 -1.49007956532211 1.57079632679488" xyz="0 0.1225 0"/>
    <parent link="jaco_1_shoulder_limb"/>
    <child link="jaco_ring_2"/>
    <axis xyz="0 0 0"/>
  </joint>
  <!-- ...........................        -->
  <link name="jaco_2_upperarm_limb">
    <inertial>
      <origin rpy="0 0 0" xyz="0.206003857152394 0 -0.0343672381612413"/>
      <mass value="1.37163"/>
      <inertia ixx="0.02826723808809537" ixy="0" ixz="0" iyy="0.02826723808809537" iyz="0" izz="0.001646641815"/>
    </inertial>
    <visual>
      <origin rpy="0 0 0" xyz="-0.003 -0.001 -0.001"/>
      <geometry>
        <mesh filename="/home/colan/simulations/URDFs/robots/kinova/jaco/meshes/2_upperarm_limb.STL"/>
      </geometry>
      <material name="">
        <color rgba="0.10 0.10 0.10 1"/>
      </material>
    </visual>
    <!--     <visual>
      <origin xyz="0 0 0" rpy="0 0 0" />
      <geometry>
        <sphere radius="0.005"/>
      </geometry>
      <material name="">
        <color rgba="0.10 0.10 0.10 1" />
      </material>
    </visual>
-->
    <collision>
      <origin rpy="0 0 0" xyz="-0.003 -0.001 -0.001"/>
      <geometry>
        <mesh filename="/home/colan/simulations/URDFs/robots/kinova/jaco/meshes/2_upperarm_limb.STL"/>
      </geometry>
    </collision>
  </link>
  <joint name="jaco_arm_1_joint" type="revolute">
    <dynamics damping="0.5" friction="0.5"/>
    <limit effort="8" lower="-3.943" upper="0.81" velocity="1.0"/>
    <origin rpy="3.14159265358979 -1.5707963267949 0" xyz="0 0.1225 0"/>
    <parent link="jaco_1_shoulder_limb"/>
    <child link="jaco_2_upperarm_limb"/>
    <axis xyz="0 0 1"/>
  </joint>
  <!-- ...........................        -->
  <link name="jaco_ring_3">
    <inertial>
      <origin rpy="0 0 0" xyz="0 0 0"/>
      <mass value="0.00872"/>
      <inertia ixx="3.7786515520000004e-06" ixy="0" ixz="0" iyy="3.7786515520000004e-06" iyz="0" izz="6.976000000000001e-06"/>
    </inertial>
    <visual>
      <origin rpy="0 0 0" xyz="0.001 0 0"/>
      <geometry>
        <mesh filename="/home/colan/simulations/URDFs/robots/kinova/jaco/meshes/ring_3.STL"/>
      </geometry>
      <material name="">
        <color rgba="0.5 0.5 0.5 1"/>
      </material>
    </visual>
    <collision>
      <origin rpy="0 0 0" xyz="0.001 0 0"/>
      <geometry>
        <mesh filename="/home/colan/simulations/URDFs/robots/kinova/jaco/meshes/ring_3.STL"/>
      </geometry>
    </collision>
  </link>
  <joint name="jaco_ring_3_joint" type="fixed">
    <origin rpy="3.14159265358979 0 -3.14159265358979" xyz="0.41 0 0"/>
    <parent link="jaco_2_upperarm_limb"/>
    <child link="jaco_ring_3"/>
    <axis xyz="0 0 0"/>
  </joint>
  <!-- ........................... -->
  <link name="jaco_3_forearm_limb">
    <inertial>
      <origin rpy="0 0 0" xyz="0.0857562490792731 1.94295959371482E-06 0.0203407295609686"/>
      <mass value="0.67592919"/>
      <inertia ixx="0.0034068384724891" ixy="0" ixz="0" iyy="0.0034068384724891" iyz="0" izz="0.000324783975795"/>
    </inertial>
    <visual>
      <origin rpy="0 0 0" xyz="0 0 0"/>
      <geometry>
        <mesh filename="/home/colan/simulations/URDFs/robots/kinova/jaco/meshes/3_forearm_limb.STL"/>
      </geometry>
      <material name="">
        <color rgba="0.1 0.1 0.1 1"/>
      </material>
    </visual>
    <!--     <visual>
      <origin xyz="0 0 0" rpy="0 0 0" />
      <geometry>
        <sphere radius="0.005"/>
      </geometry>
      <material name="">
        <color rgba="0.10 0.10 0.10 1" />
      </material>
    </visual>
-->
    <collision>
      <origin rpy="0 0 0" xyz="0 0 0"/>
      <geometry>
        <mesh filename="/home/colan/simulations/URDFs/robots/kinova/jaco/meshes/3_forearm_limb.STL"/>
      </geometry>
    </collision>
  </link>
  <joint name="jaco_arm_2_joint" type="revolute">
    <limit effort="4" lower="-4.395" upper="1.252" velocity="1.0"/>
    <dynamics damping="0.5" friction="0.5"/>
    <origin rpy="0 0 1.57079632679489" xyz="0.41 0 0"/>
    <parent link="jaco_2_upperarm_limb"/>
    <child link="jaco_3_forearm_limb"/>
    <axis xyz="0 0 1"/>
  </joint>
  <!-- ...........................        -->
  <link name="jaco_ring_4">
    <inertial>
      <origin rpy="0 0 0" xyz="0 0 0"/>
      <mass value="0.00676534123968923"/>
      <inertia ixx="2.114724456907862e-06" ixy="0" ixz="0" iyy="2.114724456907862e-06" iyz="0" izz="3.6837283050107858e-06"/>
    </inertial>
    <visual>
      <origin rpy="0 0 0" xyz="0 0 0"/>
      <geometry>
        <mesh filename="/home/colan/simulations/URDFs/robots/kinova/jaco/meshes/ring_4.STL"/>
      </geometry>
      <material name="">
        <color rgba="0.5 0.5 0.5 1"/>
      </material>
    </visual>
    <collision>
      <origin rpy="0 0 0" xyz="0 0 0"/>
      <geometry>
        <mesh filename="/home/colan/simulations/URDFs/robots/kinova/jaco/meshes/ring_4.STL"/>
      </geometry>
    </collision>
  </link>
  <joint name="jaco_ring_4_joint" type="fixed">
    <origin rpy="3.14159265358979 -1.5707963267949 0" xyz="0.2073 0 0.0098"/>
    <parent link="jaco_3_forearm_limb"/>
    <child link="jaco_ring_4"/>
    <axis xyz="-1 0 0"/>
  </joint>
  <!-- ...........................        -->
  <link name="jaco_4_upperwrist_limb">
    <inertial>
      <origin rpy="0 0 0" xyz="-0.0371070560898082 -0.00912675248782567 -2.44092722145872E-08"/>
      <mass value="0.245503362859736"/>
      <inertia ixx="0.000272235953437906" ixy="0" ixz="0" iyy="0.000272235953437906" iyz="0" izz="0.0001353018133392577"/>
    </inertial>
    <visual>
      <origin rpy="0 0 0" xyz="0 0 0"/>
      <geometry>
        <mesh filename="/home/colan/simulations/URDFs/robots/kinova/jaco/meshes/4_upperwrist_limb.STL"/>
      </geometry>
      <material name="">
        <color rgba="0.1 0.1 0.1 1"/>
      </material>
    </visual>
    <!--     <visual>
      <origin xyz="0 0 0" rpy="0 0 0" />
      <geometry>
        <sphere radius="0.005"/>
      </geometry>
      <material name="">
        <color rgba="0.10 0.10 0.10 1" />
      </material>
    </visual>
-->
    <collision>
      <origin rpy="0 0 0" xyz="0 0 0"/>
      <geometry>
        <mesh filename="/home/colan/simulations/URDFs/robots/kinova/jaco/meshes/4_upperwrist_limb.STL"/>
      </geometry>
    </collision>
  </link>
  <joint name="jaco_arm_3_joint" type="revolute">
    <dynamics damping="0.05" friction="0.05"/>
    <origin rpy="-1.57079632679484 0 -3.14159265358951" xyz="0.2073 0 0.0098"/>
    <limit effort="1.5" lower="-6.283185307" upper="6.283185307" velocity="1.0"/>
    <parent link="jaco_3_forearm_limb"/>
    <child link="jaco_4_upperwrist_limb"/>
    <axis xyz="-1 0 0"/>
  </joint>
  <!-- ...........................        -->
  <link name="jaco_ring_5">
    <inertial>
      <origin rpy="0 0 0" xyz="-1.54831009124834E-13 4.27435864480685E-15 -2.58654209162046E-13"/>
      <mass value="0.00676534123968923"/>
      <inertia ixx="2.114724456907862e-06" ixy="0" ixz="0" iyy="2.114724456907862e-06" iyz="0" izz="3.6837283050107858e-06"/>
    </inertial>
    <visual>
      <origin rpy="0 0 0" xyz="0 0 0"/>
      <geometry>
        <mesh filename="/home/colan/simulations/URDFs/robots/kinova/jaco/meshes/ring_5.STL"/>
      </geometry>
      <material name="">
        <color rgba="0.5 0.5 0.5 1"/>
      </material>
    </visual>
    <collision>
      <origin rpy="0 0 0" xyz="0 0 0"/>
      <geometry>
        <mesh filename="/home/colan/simulations/URDFs/robots/kinova/jaco/meshes/ring_5.STL"/>
      </geometry>
    </collision>
  </link>
  <joint name="jaco_ring_5_joint" type="fixed">
    <origin rpy="-1.57079632679506 0 -0.610865238196312" xyz="-0.06590490 -0.034307921 0"/>
    <parent link="jaco_4_upperwrist_limb"/>
    <child link="jaco_ring_5"/>
    <axis xyz="-1 0 0"/>
  </joint>
  <!-- ...........................        -->
  <link name="jaco_5_lowerwrist_limb">
    <inertial>
      <origin rpy="0 0 0" xyz="-0.0176083455436658 -0.00912672231835664 -5.99117305766228E-09"/>
      <mass value="0.2455"/>
      <inertia ixx="0.00027223222440008" ixy="0" ixz="0" iyy="0.00027223222440008" iyz="0" izz="0.00013529995999999998"/>
    </inertial>
    <visual>
      <origin rpy="0 0 0" xyz="-0.01715 0 0"/>
      <geometry>
        <mesh filename="/home/colan/simulations/URDFs/robots/kinova/jaco/meshes/5_lowerwrist_limb.STL"/>
      </geometry>
      <material name="">
        <color rgba="0.1 0.1 0.1 1"/>
      </material>
    </visual>
    <!--     <visual>
      <origin xyz="0 0 0" rpy="0 0 0" />
      <geometry>
        <sphere radius="0.005"/>
      </geometry>
      <material name="">
        <color rgba="0.10 0.10 0.10 1" />
      </material>
    </visual>
-->
    <collision>
      <origin rpy="0 0 0" xyz="-0.01715 0 0"/>
      <geometry>
        <mesh filename="/home/colan/simulations/URDFs/robots/kinova/jaco/meshes/5_lowerwrist_limb.STL"/>
      </geometry>
    </collision>
  </link>
  <joint name="jaco_arm_4_joint" type="revolute">
    <dynamics damping="0.05" friction="0.05"/>
    <!-- caluclated form DH-Parameter documentation. An iscoceles triangle with tip angle 55 degrees has base angles (gamma) 62.5.
       Base has length 74.3. Then sin(gamma)=y/74.3 and cos(gamma)=x/74.3, hence y=65.90590 and x=34.307921963  -->
    <origin rpy="0 0 0.959931089" xyz="-0.06590490 -0.034307921 0"/>
    <limit effort="1.0" lower="-6.283185307" upper="6.283185307" velocity="1.0"/>
    <parent link="jaco_4_upperwrist_limb"/>
    <child link="jaco_5_lowerwrist_limb"/>
    <axis xyz="-1 0 0"/>
  </joint>
  <!-- ...........................        -->
  <link name="jaco_ring_6">
    <inertial>
      <origin rpy="0 0 0" xyz="2.12629684692711E-10 7.53045514834128E-10 3.03666577994299E-10"/>
      <mass value="0.00676"/>
      <inertia ixx="2.1130548810800004e-06" ixy="0" ixz="0" iyy="2.1130548810800004e-06" iyz="0" izz="3.6808200000000005e-06"/>
    </inertial>
    <visual>
      <origin rpy="0 0 0" xyz="-0.001 0 0"/>
      <geometry>
        <mesh filename="/home/colan/simulations/URDFs/robots/kinova/jaco/meshes/ring_6.STL"/>
      </geometry>
      <material name="">
        <color rgba="0.5 0.5 0.5 1"/>
      </material>
    </visual>
    <collision>
      <origin rpy="0 0 0" xyz="-0.001 0 0"/>
      <geometry>
        <mesh filename="/home/colan/simulations/URDFs/robots/kinova/jaco/meshes/ring_6.STL"/>
      </geometry>
    </collision>
  </link>
  <joint name="jaco_ring_6_joint" type="fixed">
    <origin rpy="1.5707963267949 0 2.53072741539211 " xyz="-0.06590490 -0.034307921 0"/>
    <parent link="jaco_5_lowerwrist_limb"/>
    <child link="jaco_ring_6"/>
    <axis xyz="0 0 0"/>
  </joint>
  <!-- ...........................        -->
  <link name="jaco_6_hand_limb">
    <inertial>
      <origin rpy="0 0 0" xyz="-0.0555917045329114 -7.25586546752172E-05 -0.00317411883668722"/>
      <mass value="0.2"/>
      <inertia ixx="0.0007852635256" ixy="0" ixz="0" iyy="0.0007852635256" iyz="0" izz="0.0012100000000000001"/>
    </inertial>
    <visual>
      <origin rpy="0 0 0" xyz="0 0 0"/>
      <geometry>
        <mesh filename="/home/colan/simulations/URDFs/robots/kinova/jaco/meshes/6_hand_limb.STL" scale="1.0 1.0 1.0"/>
      </geometry>
      <material name="">
        <color rgba="0.1 0.1 0.1 1"/>
      </material>
    </visual>
    <!--     <visual>
      <origin xyz="0 0 0" rpy="0 0 0" />
      <geometry>
        <sphere radius="0.005"/>
      </geometry>
      <material name="">
        <color rgba="0.10 0.10 0.10 1" />
      </material>
    </visual>
-->
    <collision>
      <origin rpy="0 0 0" xyz="0 0 0"/>
      <geometry>
        <mesh filename="/home/colan/simulations/URDFs/robots/kinova/jaco/meshes/6_hand_limb.STL" scale="1.0 1.0 1.0"/>
      </geometry>
    </collision>
  </link>
  <joint name="jaco_arm_5_joint" type="revolute">
    <dynamics damping="0.05" friction="0.05"/>
    <!-- added some experimental angle changes to the arm wrist, as this was not accurate .. tried to touch the base with the hand, and it didn't look the same
    in rviz. I tuned the values so rviz would show same position. However, it's likely this can be better fine tuned -->
    <origin rpy="-1.5707963267949 0 0.959931089" xyz="-0.06590490 -0.034307921 0"/>
    <limit effort="1.0" lower="-6.283185307" upper="6.283185307" velocity="1.0"/>
    <parent link="jaco_5_lowerwrist_limb"/>
    <child link="jaco_6_hand_limb"/>
    <axis xyz="-1 0 0"/>
  </joint>
  <link name="link_ee">
    <inertial>
      <origin rpy="0 0 0" xyz="0 0 0"/>
      <mass value="0.001"/>
      <inertia ixx="3.33332e-08" ixy="0" ixz="0" iyy="3.33332e-08" iyz="0" izz="5.0000000000000004e-08"/>
    </inertial>
  </link>
  <!-- this joint is only to align the coordinate system with the kinova specification frame -->
  <joint name="jaco_fingers_base_joint" type="fixed">
    <origin rpy="-1.5707963267949 3.14159265358979 1.5707963267949" xyz="0 0 0"/>
    <parent link="jaco_6_hand_limb"/>
    <child link="link_ee"/>
  </joint>
</robot>

