<?xml version="1.0" encoding="utf-8"?>
<robot
  name="vs050">

  <link
    name="base_link">
    <inertial>
      <origin
        xyz="0 0 0"
        rpy="0 0 0" />
      <mass
        value="6.0925" />
      <inertia
        ixx="1"
        ixy="-0.00"
        ixz="0.00"
        iyy="1"
        iyz="0"
        izz="1" />
    </inertial>
    <visual>
      <origin
        xyz="0 0 0"
        rpy="0 0 0" />
      <geometry>
        <mesh
          filename="/home/colan/simulations/URDFs/robots/denso/vs050/meshes/base_link.STL" />
      </geometry>
      <material
        name="">
        <color
          rgba="1.0 1.0 1.0 1" />
      </material>
    </visual>
    <collision>
      <origin
        xyz="0 0 0"
        rpy="0 0 0" />
      <geometry>
        <mesh
          filename="/home/colan/simulations/URDFs/robots/denso/vs050/meshes/base_link.STL" />
      </geometry>
    </collision>
  </link>

<!--  -->

  <link
    name="link1">
    <inertial>
      <origin
        xyz="0 0 0"
        rpy="0 0 0" />
      <mass
        value="2.8351" />
      <inertia
        ixx="1"
        ixy="0"
        ixz="0"
        iyy="1"
        iyz="0"
        izz="1" />
    </inertial>
    <visual>
      <origin
        xyz="-0.035 0 0.345"
        rpy="0 0 0" />
      <geometry>
        <mesh
          filename="/home/colan/simulations/URDFs/robots/denso/vs050/meshes/link1.STL" />
      </geometry>
      <material
        name="">
        <color
          rgba="1.0 1.0 1.0 1" />
      </material>
    </visual>
    <collision>
      <origin
        xyz="-0.035 0 0.345"
        rpy="0 0 0" />
      <geometry>
        <mesh
          filename="/home/colan/simulations/URDFs/robots/denso/vs050/meshes/link1.STL" />
      </geometry>
    </collision>
  </link>

  <joint name="joint_1" type="revolute">
    <parent link="base_link"/>
    <child link="link1"/>
    <origin rpy="0.0 0.0 0.0" xyz="0.0 0.0 0.0" />
    <axis xyz= "0.0 0.0 1.0" />
    <limit effort="1" lower="-2.96706" upper="2.96706" velocity="3.92699081698724" />
    <dynamics damping="0" friction="0" />
  </joint>

<!--  -->

  <link
    name="link2">
    <inertial>
      <origin
        xyz="0 0 0"
        rpy="0 0 0" />
      <mass
        value="3.4626" />
      <inertia
        ixx="1"
        ixy="0"
        ixz="0"
        iyy="1"
        iyz="0"
        izz="1" />
    </inertial>
    <visual>
      <origin
        xyz="0 0 0"
        rpy="0 0 0" />
      <geometry>
        <mesh
          filename="/home/colan/simulations/URDFs/robots/denso/vs050/meshes/link2.STL" />
      </geometry>
      <material
        name="">
        <color
          rgba="1.0 1.0 1.0 1" />
      </material>
    </visual>
    <collision>
      <origin
        xyz="0 0 0"
        rpy="0 0 0" />
      <geometry>
        <mesh
          filename="/home/colan/simulations/URDFs/robots/denso/vs050/meshes/link2.STL" />
      </geometry>
    </collision>
  </link>

  <joint name="joint_2" type="revolute">
    <parent link="link1"/>
    <child link="link2"/>
    <origin rpy="0.0 0.0 0.0" xyz="0.0 0.0 0.345" />
    <axis xyz= "0.0 1.0 0.0" />
    <limit effort="1" lower="-2.094395" upper="2.094395" velocity="2.61799387799149" />
    <dynamics damping="0" friction="0" />
  </joint>

<!--  -->

  <link
    name="link3">
    <inertial>
      <origin
        xyz="0 0 0"
        rpy="0 0 0" />
      <mass
        value="1.492" />
      <inertia
        ixx="1"
        ixy="0"
        ixz="0"
        iyy="1"
        iyz="0"
        izz="1" />
    </inertial>
    <visual>
      <origin
        xyz="0 0 0"
        rpy="0 0 0" />
      <geometry>
        <mesh
          filename="/home/colan/simulations/URDFs/robots/denso/vs050/meshes/link3.STL" />
      </geometry>
      <material
        name="">
        <color
          rgba="1.0 1.0 1.0 1" />
      </material>
    </visual>
    <collision>
      <origin
        xyz="0 0 0"
        rpy="0 0 0" />
      <geometry>
        <mesh
          filename="/home/colan/simulations/URDFs/robots/denso/vs050/meshes/link3.STL" />
      </geometry>
    </collision>
  </link>

  <joint name="joint_3" type="revolute">
    <parent link="link2"/>
    <child link="link3"/>
    <origin rpy="0.0 0.0 0.0" xyz="0.0 0.0 0.25" />
    <axis xyz= "0.0 1.0 0.0" />
    <limit effort="1" lower="-2.181662" upper="2.70526" velocity="2.85832571599111" />
    <dynamics damping="0" friction="0" />
  </joint>

<!--  -->

  <link
    name="link4">
    <inertial>
      <origin
        xyz="0 0 0"
        rpy="0 0 0" />
      <mass
        value="0.98124" />
      <inertia
        ixx="1"
        ixy="0"
        ixz="0"
        iyy="1"
        iyz="0"
        izz="1" />
    </inertial>
    <visual>
      <origin
        xyz="0 0 0.850"
        rpy="0 0 0" />
      <geometry>
        <mesh
          filename="/home/colan/simulations/URDFs/robots/denso/vs050/meshes/link4.STL" />
      </geometry>
      <material
        name="">
        <color
          rgba="1.0 1.0 1.0 1" />
      </material>
    </visual>
    <collision>
      <origin
        xyz="0 0 0.850"
        rpy="0 0 0" />
      <geometry>
        <mesh
          filename="/home/colan/simulations/URDFs/robots/denso/vs050/meshes/link4.STL" />
      </geometry>
    </collision>
  </link>

  <joint name="joint_4" type="revolute">
    <parent link="link3"/>
    <child link="link4"/>
    <origin rpy="0.0 0.0 0.0" xyz="-0.01 0.0 -0.595" />
    <axis xyz= "0.0 0.0 1.0" />
    <limit effort="1" lower="-4.712389" upper="4.712389" velocity="3.92699081698724" />
    <dynamics damping="0" friction="0" />
  </joint>

<!--  -->

  <link
    name="link5">
    <inertial>
      <origin
        xyz="0 0 0"
        rpy="0 0 0" />
      <mass
        value="0.41203" />
      <inertia
        ixx="1"
        ixy="0"
        ixz="0"
        iyy="1"
        iyz="0"
        izz="1" />
    </inertial>
    <visual>
      <origin
        xyz="0 0 0"
        rpy="0 0 0" />
      <geometry>
        <mesh
          filename="/home/colan/simulations/URDFs/robots/denso/vs050/meshes/link5.STL" />
      </geometry>
      <material
        name="">
        <color
          rgba="0.4 0.4 0.4 1" />
      </material>
    </visual>
    <collision>
      <origin
        xyz="0 0 0"
        rpy="0 0 0" />
      <geometry>
        <mesh
          filename="/home/colan/simulations/URDFs/robots/denso/vs050/meshes/link5.STL" />
      </geometry>
    </collision>
  </link>

  <joint name="joint_5" type="revolute">
    <parent link="link4"/>
    <child link="link5"/>
    <origin rpy="0.0 0.0 0.0" xyz="0.0 0.0 0.85" />
    <axis xyz= "0.0 1.0 0.0" />
    <limit effort="1" lower="-2.094395" upper="2.094395" velocity="3.02168853397778" />
    <dynamics damping="0" friction="0" />
  </joint>


<!--  -->
  <link
    name="link_ee">
  </link>

  <joint name="joint_6" type="revolute">
    <parent link="link5"/>
    <child link="link_ee"/>
    <origin rpy="0.0 0.0 0.0" xyz="0.0 0.0 0.07" />
    <axis xyz= "0.0 0.0 1.0" />
    <limit effort="1" lower="-6.283185" upper="6.283185" velocity="6.28318530717959" />
    <dynamics damping="0" friction="0" />
  </joint>


</robot>
